2024-03-22 15:21:44,600 INFO pygame.joystick.get_count: 0
2024-03-22 15:21:44,600 INFO pygame.joystick.get_init: True
2024-03-22 15:21:46,649 ERROR Error: Error 10061 connecting to 10.0.1.35:6379. No connection could be made because the target machine actively refused it.
Traceback (most recent call last):
  File "C:\Users\stage\miniconda3\envs\tf\lib\site-packages\redis\connection.py", line 276, in connect
    sock = self.retry.call_with_retry(
  File "C:\Users\stage\miniconda3\envs\tf\lib\site-packages\redis\retry.py", line 46, in call_with_retry
    return do()
  File "C:\Users\stage\miniconda3\envs\tf\lib\site-packages\redis\connection.py", line 277, in <lambda>
    lambda: self._connect(), lambda error: self.disconnect(error)
  File "C:\Users\stage\miniconda3\envs\tf\lib\site-packages\redis\connection.py", line 639, in _connect
    raise err
  File "C:\Users\stage\miniconda3\envs\tf\lib\site-packages\redis\connection.py", line 627, in _connect
    sock.connect(socket_address)
ConnectionRefusedError: [WinError 10061] No connection could be made because the target machine actively refused it

During handling of the above exception, another exception occurred:

Traceback (most recent call last):
  File "c:\Users\stage\Documents\affective_touch\unity_congruency\user_input.py", line 439, in <module>
    main(output_path)
  File "c:\Users\stage\Documents\affective_touch\unity_congruency\user_input.py", line 204, in main
    set_user_input_done()
  File "c:\Users\stage\Documents\affective_touch\unity_congruency\user_input.py", line 113, in set_user_input_done
    r.set(c.REDIS_USER_GAVE_INPUT_KEY, "true")
  File "C:\Users\stage\miniconda3\envs\tf\lib\site-packages\redis\commands\core.py", line 2342, in set
    return self.execute_command("SET", *pieces, **options)
  File "C:\Users\stage\miniconda3\envs\tf\lib\site-packages\redis\client.py", line 540, in execute_command
    conn = self.connection or pool.get_connection(command_name, **options)
  File "C:\Users\stage\miniconda3\envs\tf\lib\site-packages\redis\connection.py", line 1104, in get_connection
    connection.connect()
  File "C:\Users\stage\miniconda3\envs\tf\lib\site-packages\redis\connection.py", line 282, in connect
    raise ConnectionError(self._error_message(e))
redis.exceptions.ConnectionError: Error 10061 connecting to 10.0.1.35:6379. No connection could be made because the target machine actively refused it.
2024-03-22 15:22:26,417 INFO pygame.joystick.get_count: 0
2024-03-22 15:22:26,418 INFO pygame.joystick.get_init: True
2024-03-22 15:22:28,478 ERROR Error: Error 10061 connecting to 10.0.1.35:6379. No connection could be made because the target machine actively refused it.
Traceback (most recent call last):
  File "C:\Users\stage\miniconda3\envs\tf\lib\site-packages\redis\connection.py", line 276, in connect
    sock = self.retry.call_with_retry(
  File "C:\Users\stage\miniconda3\envs\tf\lib\site-packages\redis\retry.py", line 46, in call_with_retry
    return do()
  File "C:\Users\stage\miniconda3\envs\tf\lib\site-packages\redis\connection.py", line 277, in <lambda>
    lambda: self._connect(), lambda error: self.disconnect(error)
  File "C:\Users\stage\miniconda3\envs\tf\lib\site-packages\redis\connection.py", line 639, in _connect
    raise err
  File "C:\Users\stage\miniconda3\envs\tf\lib\site-packages\redis\connection.py", line 627, in _connect
    sock.connect(socket_address)
ConnectionRefusedError: [WinError 10061] No connection could be made because the target machine actively refused it

During handling of the above exception, another exception occurred:

Traceback (most recent call last):
  File "c:\Users\stage\Documents\affective_touch\unity_congruency\user_input.py", line 439, in <module>
    main(output_path)
  File "c:\Users\stage\Documents\affective_touch\unity_congruency\user_input.py", line 204, in main
    set_user_input_done()
  File "c:\Users\stage\Documents\affective_touch\unity_congruency\user_input.py", line 113, in set_user_input_done
    r.set(c.REDIS_USER_GAVE_INPUT_KEY, "true")
  File "C:\Users\stage\miniconda3\envs\tf\lib\site-packages\redis\commands\core.py", line 2342, in set
    return self.execute_command("SET", *pieces, **options)
  File "C:\Users\stage\miniconda3\envs\tf\lib\site-packages\redis\client.py", line 540, in execute_command
    conn = self.connection or pool.get_connection(command_name, **options)
  File "C:\Users\stage\miniconda3\envs\tf\lib\site-packages\redis\connection.py", line 1104, in get_connection
    connection.connect()
  File "C:\Users\stage\miniconda3\envs\tf\lib\site-packages\redis\connection.py", line 282, in connect
    raise ConnectionError(self._error_message(e))
redis.exceptions.ConnectionError: Error 10061 connecting to 10.0.1.35:6379. No connection could be made because the target machine actively refused it.
2024-03-22 15:22:39,418 INFO pygame.joystick.get_count: 0
2024-03-22 15:22:39,418 INFO pygame.joystick.get_init: True
2024-03-22 15:24:11,238 INFO pygame.joystick.get_count: 0
2024-03-22 15:24:11,238 INFO pygame.joystick.get_init: True
